[2024-08-28T13:31:27.684+0000] {taskinstance.py:1956} INFO - Dependencies all met for dep_context=non-requeueable deps ti=<TaskInstance: welcome_dag.print_random_quote manual__2024-08-28T13:31:19.306521+00:00 [queued]>
[2024-08-28T13:31:27.692+0000] {taskinstance.py:1956} INFO - Dependencies all met for dep_context=requeueable deps ti=<TaskInstance: welcome_dag.print_random_quote manual__2024-08-28T13:31:19.306521+00:00 [queued]>
[2024-08-28T13:31:27.693+0000] {taskinstance.py:2170} INFO - Starting attempt 1 of 1
[2024-08-28T13:31:27.706+0000] {taskinstance.py:2191} INFO - Executing <Task(PythonOperator): print_random_quote> on 2024-08-28 13:31:19.306521+00:00
[2024-08-28T13:31:27.711+0000] {standard_task_runner.py:60} INFO - Started process 67 to run task
[2024-08-28T13:31:27.714+0000] {standard_task_runner.py:87} INFO - Running: ['***', 'tasks', 'run', 'welcome_dag', 'print_random_quote', 'manual__2024-08-28T13:31:19.306521+00:00', '--job-id', '12', '--raw', '--subdir', 'DAGS_FOLDER/welcome_dag.py', '--cfg-path', '/tmp/tmptkgn13pd']
[2024-08-28T13:31:27.716+0000] {standard_task_runner.py:88} INFO - Job 12: Subtask print_random_quote
[2024-08-28T13:31:27.759+0000] {task_command.py:423} INFO - Running <TaskInstance: welcome_dag.print_random_quote manual__2024-08-28T13:31:19.306521+00:00 [running]> on host 806dd18644e1
[2024-08-28T13:31:27.819+0000] {taskinstance.py:2480} INFO - Exporting env vars: AIRFLOW_CTX_DAG_OWNER='***' AIRFLOW_CTX_DAG_ID='welcome_dag' AIRFLOW_CTX_TASK_ID='print_random_quote' AIRFLOW_CTX_EXECUTION_DATE='2024-08-28T13:31:19.306521+00:00' AIRFLOW_CTX_TRY_NUMBER='1' AIRFLOW_CTX_DAG_RUN_ID='manual__2024-08-28T13:31:19.306521+00:00'
[2024-08-28T13:31:28.653+0000] {taskinstance.py:2698} ERROR - Task failed with exception
Traceback (most recent call last):
  File "/home/airflow/.local/lib/python3.8/site-packages/urllib3/connection.py", line 174, in _new_conn
    conn = connection.create_connection(
  File "/home/airflow/.local/lib/python3.8/site-packages/urllib3/util/connection.py", line 72, in create_connection
    for res in socket.getaddrinfo(host, port, family, socket.SOCK_STREAM):
  File "/usr/local/lib/python3.8/socket.py", line 918, in getaddrinfo
    for res in _socket.getaddrinfo(host, port, family, type, proto, flags):
socket.gaierror: [Errno -2] Name or service not known

During handling of the above exception, another exception occurred:

Traceback (most recent call last):
  File "/home/airflow/.local/lib/python3.8/site-packages/urllib3/connectionpool.py", line 715, in urlopen
    httplib_response = self._make_request(
  File "/home/airflow/.local/lib/python3.8/site-packages/urllib3/connectionpool.py", line 404, in _make_request
    self._validate_conn(conn)
  File "/home/airflow/.local/lib/python3.8/site-packages/urllib3/connectionpool.py", line 1058, in _validate_conn
    conn.connect()
  File "/home/airflow/.local/lib/python3.8/site-packages/urllib3/connection.py", line 363, in connect
    self.sock = conn = self._new_conn()
  File "/home/airflow/.local/lib/python3.8/site-packages/urllib3/connection.py", line 186, in _new_conn
    raise NewConnectionError(
urllib3.exceptions.NewConnectionError: <urllib3.connection.HTTPSConnection object at 0x7fd6039ef4f0>: Failed to establish a new connection: [Errno -2] Name or service not known

During handling of the above exception, another exception occurred:

Traceback (most recent call last):
  File "/home/airflow/.local/lib/python3.8/site-packages/requests/adapters.py", line 486, in send
    resp = conn.urlopen(
  File "/home/airflow/.local/lib/python3.8/site-packages/urllib3/connectionpool.py", line 799, in urlopen
    retries = retries.increment(
  File "/home/airflow/.local/lib/python3.8/site-packages/urllib3/util/retry.py", line 592, in increment
    raise MaxRetryError(_pool, url, error or ResponseError(cause))
urllib3.exceptions.MaxRetryError: HTTPSConnectionPool(host='api.quotable.io', port=443): Max retries exceeded with url: /random (Caused by NewConnectionError('<urllib3.connection.HTTPSConnection object at 0x7fd6039ef4f0>: Failed to establish a new connection: [Errno -2] Name or service not known'))

During handling of the above exception, another exception occurred:

Traceback (most recent call last):
  File "/home/airflow/.local/lib/python3.8/site-packages/airflow/models/taskinstance.py", line 433, in _execute_task
    result = execute_callable(context=context, **execute_callable_kwargs)
  File "/home/airflow/.local/lib/python3.8/site-packages/airflow/operators/python.py", line 199, in execute
    return_value = self.execute_callable()
  File "/home/airflow/.local/lib/python3.8/site-packages/airflow/operators/python.py", line 216, in execute_callable
    return self.python_callable(*self.op_args, **self.op_kwargs)
  File "/opt/airflow/dags/welcome_dag.py", line 27, in print_random_quote
    response = requests.get('https://api.quotable.io/random')
  File "/home/airflow/.local/lib/python3.8/site-packages/requests/api.py", line 73, in get
    return request("get", url, params=params, **kwargs)
  File "/home/airflow/.local/lib/python3.8/site-packages/requests/api.py", line 59, in request
    return session.request(method=method, url=url, **kwargs)
  File "/home/airflow/.local/lib/python3.8/site-packages/requests/sessions.py", line 589, in request
    resp = self.send(prep, **send_kwargs)
  File "/home/airflow/.local/lib/python3.8/site-packages/requests/sessions.py", line 703, in send
    r = adapter.send(request, **kwargs)
  File "/home/airflow/.local/lib/python3.8/site-packages/requests/adapters.py", line 519, in send
    raise ConnectionError(e, request=request)
requests.exceptions.ConnectionError: HTTPSConnectionPool(host='api.quotable.io', port=443): Max retries exceeded with url: /random (Caused by NewConnectionError('<urllib3.connection.HTTPSConnection object at 0x7fd6039ef4f0>: Failed to establish a new connection: [Errno -2] Name or service not known'))
[2024-08-28T13:31:28.667+0000] {taskinstance.py:1138} INFO - Marking task as FAILED. dag_id=welcome_dag, task_id=print_random_quote, execution_date=20240828T133119, start_date=20240828T133127, end_date=20240828T133128
[2024-08-28T13:31:28.679+0000] {standard_task_runner.py:107} ERROR - Failed to execute job 12 for task print_random_quote (HTTPSConnectionPool(host='api.quotable.io', port=443): Max retries exceeded with url: /random (Caused by NewConnectionError('<urllib3.connection.HTTPSConnection object at 0x7fd6039ef4f0>: Failed to establish a new connection: [Errno -2] Name or service not known')); 67)
[2024-08-28T13:31:28.693+0000] {local_task_job_runner.py:234} INFO - Task exited with return code 1
[2024-08-28T13:31:28.708+0000] {taskinstance.py:3280} INFO - 0 downstream tasks scheduled from follow-on schedule check
